[2025-08-25T14:29:09.468+0000] {taskinstance.py:1979} INFO - Dependencies all met for dep_context=non-requeueable deps ti=<TaskInstance: mamda_monthly_etl_pipeline.run_db_to_file_etl manual__2025-08-25T14:29:06.051044+00:00 [queued]>
[2025-08-25T14:29:09.477+0000] {taskinstance.py:1979} INFO - Dependencies all met for dep_context=requeueable deps ti=<TaskInstance: mamda_monthly_etl_pipeline.run_db_to_file_etl manual__2025-08-25T14:29:06.051044+00:00 [queued]>
[2025-08-25T14:29:09.478+0000] {taskinstance.py:2193} INFO - Starting attempt 1 of 1
[2025-08-25T14:29:09.492+0000] {taskinstance.py:2214} INFO - Executing <Task(PythonOperator): run_db_to_file_etl> on 2025-08-25 14:29:06.051044+00:00
[2025-08-25T14:29:09.499+0000] {standard_task_runner.py:60} INFO - Started process 1234 to run task
[2025-08-25T14:29:09.502+0000] {standard_task_runner.py:87} INFO - Running: ['***', 'tasks', 'run', 'mamda_monthly_etl_pipeline', 'run_db_to_file_etl', 'manual__2025-08-25T14:29:06.051044+00:00', '--job-id', '86', '--raw', '--subdir', 'DAGS_FOLDER/mamda_monthly_etl.py', '--cfg-path', '/tmp/tmpqbfex85q']
[2025-08-25T14:29:09.503+0000] {standard_task_runner.py:88} INFO - Job 86: Subtask run_db_to_file_etl
[2025-08-25T14:29:09.557+0000] {task_command.py:423} INFO - Running <TaskInstance: mamda_monthly_etl_pipeline.run_db_to_file_etl manual__2025-08-25T14:29:06.051044+00:00 [running]> on host 9f5b6f3413d6
[2025-08-25T14:29:09.653+0000] {taskinstance.py:2510} INFO - Exporting env vars: AIRFLOW_CTX_DAG_OWNER='mamda_etl' AIRFLOW_CTX_DAG_ID='mamda_monthly_etl_pipeline' AIRFLOW_CTX_TASK_ID='run_db_to_file_etl' AIRFLOW_CTX_EXECUTION_DATE='2025-08-25T14:29:06.051044+00:00' AIRFLOW_CTX_TRY_NUMBER='1' AIRFLOW_CTX_DAG_RUN_ID='manual__2025-08-25T14:29:06.051044+00:00'
[2025-08-25T14:29:09.654+0000] {mamda_monthly_etl.py:101} INFO - === START: DB -> FILE ETL ===
[2025-08-25T14:29:09.656+0000] {taskinstance.py:2728} ERROR - Task failed with exception
Traceback (most recent call last):
  File "/home/airflow/.local/lib/python3.11/site-packages/airflow/models/taskinstance.py", line 444, in _execute_task
    result = _execute_callable(context=context, **execute_callable_kwargs)
             ^^^^^^^^^^^^^^^^^^^^^^^^^^^^^^^^^^^^^^^^^^^^^^^^^^^^^^^^^^^^^
  File "/home/airflow/.local/lib/python3.11/site-packages/airflow/models/taskinstance.py", line 414, in _execute_callable
    return execute_callable(context=context, **execute_callable_kwargs)
           ^^^^^^^^^^^^^^^^^^^^^^^^^^^^^^^^^^^^^^^^^^^^^^^^^^^^^^^^^^^^
  File "/home/airflow/.local/lib/python3.11/site-packages/airflow/operators/python.py", line 200, in execute
    return_value = self.execute_callable()
                   ^^^^^^^^^^^^^^^^^^^^^^^
  File "/home/airflow/.local/lib/python3.11/site-packages/airflow/operators/python.py", line 217, in execute_callable
    return self.python_callable(*self.op_args, **self.op_kwargs)
           ^^^^^^^^^^^^^^^^^^^^^^^^^^^^^^^^^^^^^^^^^^^^^^^^^^^^^
  File "/opt/airflow/dags/mamda_monthly_etl.py", line 102, in run_db_to_file_etl
    env = _compose_env_for_subprocess()
          ^^^^^^^^^^^^^^^^^^^^^^^^^^^^^
  File "/opt/airflow/dags/mamda_monthly_etl.py", line 64, in _compose_env_for_subprocess
    os.makedirs(fee_payouts, exist_ok=True)
  File "<frozen os>", line 225, in makedirs
FileExistsError: [Errno 17] File exists: '/opt/airflow/data/fee_payouts'
[2025-08-25T14:29:09.670+0000] {taskinstance.py:1149} INFO - Marking task as FAILED. dag_id=mamda_monthly_etl_pipeline, task_id=run_db_to_file_etl, execution_date=20250825T142906, start_date=20250825T142909, end_date=20250825T142909
[2025-08-25T14:29:09.682+0000] {standard_task_runner.py:107} ERROR - Failed to execute job 86 for task run_db_to_file_etl ([Errno 17] File exists: '/opt/airflow/data/fee_payouts'; 1234)
[2025-08-25T14:29:09.715+0000] {local_task_job_runner.py:234} INFO - Task exited with return code 1
[2025-08-25T14:29:09.739+0000] {taskinstance.py:3309} INFO - 0 downstream tasks scheduled from follow-on schedule check
