[2025-08-26T10:04:49.151+0000] {taskinstance.py:1979} INFO - Dependencies all met for dep_context=non-requeueable deps ti=<TaskInstance: mamda_monthly_etl_pipeline.run_db_to_file_etl manual__2025-08-26T10:04:45.703707+00:00 [queued]>
[2025-08-26T10:04:49.161+0000] {taskinstance.py:1979} INFO - Dependencies all met for dep_context=requeueable deps ti=<TaskInstance: mamda_monthly_etl_pipeline.run_db_to_file_etl manual__2025-08-26T10:04:45.703707+00:00 [queued]>
[2025-08-26T10:04:49.162+0000] {taskinstance.py:2193} INFO - Starting attempt 1 of 1
[2025-08-26T10:04:49.176+0000] {taskinstance.py:2214} INFO - Executing <Task(PythonOperator): run_db_to_file_etl> on 2025-08-26 10:04:45.703707+00:00
[2025-08-26T10:04:49.184+0000] {standard_task_runner.py:60} INFO - Started process 146 to run task
[2025-08-26T10:04:49.188+0000] {standard_task_runner.py:87} INFO - Running: ['***', 'tasks', 'run', 'mamda_monthly_etl_pipeline', 'run_db_to_file_etl', 'manual__2025-08-26T10:04:45.703707+00:00', '--job-id', '198', '--raw', '--subdir', 'DAGS_FOLDER/mamda_monthly_etl.py', '--cfg-path', '/tmp/tmpvgw9a693']
[2025-08-26T10:04:49.190+0000] {standard_task_runner.py:88} INFO - Job 198: Subtask run_db_to_file_etl
[2025-08-26T10:04:49.243+0000] {task_command.py:423} INFO - Running <TaskInstance: mamda_monthly_etl_pipeline.run_db_to_file_etl manual__2025-08-26T10:04:45.703707+00:00 [running]> on host c7bb110c70ae
[2025-08-26T10:04:49.328+0000] {taskinstance.py:2510} INFO - Exporting env vars: AIRFLOW_CTX_DAG_OWNER='mamda_etl' AIRFLOW_CTX_DAG_ID='mamda_monthly_etl_pipeline' AIRFLOW_CTX_TASK_ID='run_db_to_file_etl' AIRFLOW_CTX_EXECUTION_DATE='2025-08-26T10:04:45.703707+00:00' AIRFLOW_CTX_TRY_NUMBER='1' AIRFLOW_CTX_DAG_RUN_ID='manual__2025-08-26T10:04:45.703707+00:00'
[2025-08-26T10:04:49.329+0000] {mamda_monthly_etl.py:94} INFO - === START: DB -> FILE ETL ===
[2025-08-26T10:04:49.331+0000] {taskinstance.py:2728} ERROR - Task failed with exception
Traceback (most recent call last):
  File "/home/airflow/.local/lib/python3.11/site-packages/airflow/models/taskinstance.py", line 444, in _execute_task
    result = _execute_callable(context=context, **execute_callable_kwargs)
             ^^^^^^^^^^^^^^^^^^^^^^^^^^^^^^^^^^^^^^^^^^^^^^^^^^^^^^^^^^^^^
  File "/home/airflow/.local/lib/python3.11/site-packages/airflow/models/taskinstance.py", line 414, in _execute_callable
    return execute_callable(context=context, **execute_callable_kwargs)
           ^^^^^^^^^^^^^^^^^^^^^^^^^^^^^^^^^^^^^^^^^^^^^^^^^^^^^^^^^^^^
  File "/home/airflow/.local/lib/python3.11/site-packages/airflow/operators/python.py", line 200, in execute
    return_value = self.execute_callable()
                   ^^^^^^^^^^^^^^^^^^^^^^^
  File "/home/airflow/.local/lib/python3.11/site-packages/airflow/operators/python.py", line 217, in execute_callable
    return self.python_callable(*self.op_args, **self.op_kwargs)
           ^^^^^^^^^^^^^^^^^^^^^^^^^^^^^^^^^^^^^^^^^^^^^^^^^^^^^
  File "/opt/airflow/dags/mamda_monthly_etl.py", line 95, in run_db_to_file_etl
    env = _compose_env_for_subprocess()
          ^^^^^^^^^^^^^^^^^^^^^^^^^^^^^
  File "/opt/airflow/dags/mamda_monthly_etl.py", line 76, in _compose_env_for_subprocess
    os.makedirs(local_payouts, exist_ok=True)
  File "<frozen os>", line 225, in makedirs
FileExistsError: [Errno 17] File exists: '/opt/airflow/data/fee_payouts'
[2025-08-26T10:04:49.347+0000] {taskinstance.py:1149} INFO - Marking task as FAILED. dag_id=mamda_monthly_etl_pipeline, task_id=run_db_to_file_etl, execution_date=20250826T100445, start_date=20250826T100449, end_date=20250826T100449
[2025-08-26T10:04:49.359+0000] {standard_task_runner.py:107} ERROR - Failed to execute job 198 for task run_db_to_file_etl ([Errno 17] File exists: '/opt/airflow/data/fee_payouts'; 146)
[2025-08-26T10:04:49.402+0000] {local_task_job_runner.py:234} INFO - Task exited with return code 1
[2025-08-26T10:04:49.422+0000] {taskinstance.py:3309} INFO - 0 downstream tasks scheduled from follow-on schedule check
