[2025-08-26T09:21:55.222+0000] {taskinstance.py:1979} INFO - Dependencies all met for dep_context=non-requeueable deps ti=<TaskInstance: mamda_monthly_etl_pipeline.check_status_files manual__2025-08-26T09:21:53.276239+00:00 [queued]>
[2025-08-26T09:21:55.232+0000] {taskinstance.py:1979} INFO - Dependencies all met for dep_context=requeueable deps ti=<TaskInstance: mamda_monthly_etl_pipeline.check_status_files manual__2025-08-26T09:21:53.276239+00:00 [queued]>
[2025-08-26T09:21:55.232+0000] {taskinstance.py:2193} INFO - Starting attempt 1 of 1
[2025-08-26T09:21:55.246+0000] {taskinstance.py:2214} INFO - Executing <Task(PythonOperator): check_status_files> on 2025-08-26 09:21:53.276239+00:00
[2025-08-26T09:21:55.252+0000] {standard_task_runner.py:60} INFO - Started process 214 to run task
[2025-08-26T09:21:55.255+0000] {standard_task_runner.py:87} INFO - Running: ['***', 'tasks', 'run', 'mamda_monthly_etl_pipeline', 'check_status_files', 'manual__2025-08-26T09:21:53.276239+00:00', '--job-id', '152', '--raw', '--subdir', 'DAGS_FOLDER/mamda_monthly_etl.py', '--cfg-path', '/tmp/tmpcwydujb7']
[2025-08-26T09:21:55.256+0000] {standard_task_runner.py:88} INFO - Job 152: Subtask check_status_files
[2025-08-26T09:21:55.303+0000] {task_command.py:423} INFO - Running <TaskInstance: mamda_monthly_etl_pipeline.check_status_files manual__2025-08-26T09:21:53.276239+00:00 [running]> on host 9f5b6f3413d6
[2025-08-26T09:21:55.386+0000] {taskinstance.py:2510} INFO - Exporting env vars: AIRFLOW_CTX_DAG_OWNER='mamda_etl' AIRFLOW_CTX_DAG_ID='mamda_monthly_etl_pipeline' AIRFLOW_CTX_TASK_ID='check_status_files' AIRFLOW_CTX_EXECUTION_DATE='2025-08-26T09:21:53.276239+00:00' AIRFLOW_CTX_TRY_NUMBER='1' AIRFLOW_CTX_DAG_RUN_ID='manual__2025-08-26T09:21:53.276239+00:00'
[2025-08-26T09:21:55.388+0000] {mamda_monthly_etl.py:124} INFO - === CHECK: STATUS FILES ===
[2025-08-26T09:21:55.392+0000] {taskinstance.py:2728} ERROR - Task failed with exception
Traceback (most recent call last):
  File "/home/airflow/.local/lib/python3.11/site-packages/airflow/models/taskinstance.py", line 444, in _execute_task
    result = _execute_callable(context=context, **execute_callable_kwargs)
             ^^^^^^^^^^^^^^^^^^^^^^^^^^^^^^^^^^^^^^^^^^^^^^^^^^^^^^^^^^^^^
  File "/home/airflow/.local/lib/python3.11/site-packages/airflow/models/taskinstance.py", line 414, in _execute_callable
    return execute_callable(context=context, **execute_callable_kwargs)
           ^^^^^^^^^^^^^^^^^^^^^^^^^^^^^^^^^^^^^^^^^^^^^^^^^^^^^^^^^^^^
  File "/home/airflow/.local/lib/python3.11/site-packages/airflow/operators/python.py", line 200, in execute
    return_value = self.execute_callable()
                   ^^^^^^^^^^^^^^^^^^^^^^^
  File "/home/airflow/.local/lib/python3.11/site-packages/airflow/operators/python.py", line 217, in execute_callable
    return self.python_callable(*self.op_args, **self.op_kwargs)
           ^^^^^^^^^^^^^^^^^^^^^^^^^^^^^^^^^^^^^^^^^^^^^^^^^^^^^
  File "/opt/airflow/dags/mamda_monthly_etl.py", line 148, in check_for_new_status_files
    local_status.mkdir(parents=True, exist_ok=True)
  File "/usr/local/lib/python3.11/pathlib.py", line 1116, in mkdir
    os.mkdir(self, mode)
FileExistsError: [Errno 17] File exists: '/opt/airflow/data/fee_payouts_status'
[2025-08-26T09:21:55.421+0000] {taskinstance.py:1149} INFO - Marking task as FAILED. dag_id=mamda_monthly_etl_pipeline, task_id=check_status_files, execution_date=20250826T092153, start_date=20250826T092155, end_date=20250826T092155
[2025-08-26T09:21:55.434+0000] {standard_task_runner.py:107} ERROR - Failed to execute job 152 for task check_status_files ([Errno 17] File exists: '/opt/airflow/data/fee_payouts_status'; 214)
[2025-08-26T09:21:55.468+0000] {local_task_job_runner.py:234} INFO - Task exited with return code 1
[2025-08-26T09:21:55.493+0000] {taskinstance.py:3309} INFO - 0 downstream tasks scheduled from follow-on schedule check
