[2025-08-19T09:04:03.014+0000] {taskinstance.py:1979} INFO - Dependencies all met for dep_context=non-requeueable deps ti=<TaskInstance: mamda_monthly_etl_pipeline.run_db_to_file_etl manual__2025-08-19T08:53:57.651167+00:00 [queued]>
[2025-08-19T09:04:03.024+0000] {taskinstance.py:1979} INFO - Dependencies all met for dep_context=requeueable deps ti=<TaskInstance: mamda_monthly_etl_pipeline.run_db_to_file_etl manual__2025-08-19T08:53:57.651167+00:00 [queued]>
[2025-08-19T09:04:03.024+0000] {taskinstance.py:2193} INFO - Starting attempt 2 of 3
[2025-08-19T09:04:03.039+0000] {taskinstance.py:2214} INFO - Executing <Task(PythonOperator): run_db_to_file_etl> on 2025-08-19 08:53:57.651167+00:00
[2025-08-19T09:04:03.045+0000] {standard_task_runner.py:60} INFO - Started process 294 to run task
[2025-08-19T09:04:03.047+0000] {standard_task_runner.py:87} INFO - Running: ['***', 'tasks', 'run', 'mamda_monthly_etl_pipeline', 'run_db_to_file_etl', 'manual__2025-08-19T08:53:57.651167+00:00', '--job-id', '25', '--raw', '--subdir', 'DAGS_FOLDER/mamda_monthly_etl.py', '--cfg-path', '/tmp/tmp57c34c2b']
[2025-08-19T09:04:03.049+0000] {standard_task_runner.py:88} INFO - Job 25: Subtask run_db_to_file_etl
[2025-08-19T09:04:03.101+0000] {task_command.py:423} INFO - Running <TaskInstance: mamda_monthly_etl_pipeline.run_db_to_file_etl manual__2025-08-19T08:53:57.651167+00:00 [running]> on host 62d1bb0496b0
[2025-08-19T09:04:03.175+0000] {taskinstance.py:2510} INFO - Exporting env vars: AIRFLOW_CTX_DAG_OWNER='mamda_etl' AIRFLOW_CTX_DAG_ID='mamda_monthly_etl_pipeline' AIRFLOW_CTX_TASK_ID='run_db_to_file_etl' AIRFLOW_CTX_EXECUTION_DATE='2025-08-19T08:53:57.651167+00:00' AIRFLOW_CTX_TRY_NUMBER='2' AIRFLOW_CTX_DAG_RUN_ID='manual__2025-08-19T08:53:57.651167+00:00'
[2025-08-19T09:04:03.176+0000] {mamda_monthly_etl.py:75} INFO - === START: DB -> FILE ETL ===
[2025-08-19T09:04:03.917+0000] {mamda_monthly_etl.py:91} WARNING - DB->FILE STDERR:
Traceback (most recent call last):
  File "/opt/***/scripts/etl_pipeline_db_to_file.py", line 7, in <module>
    from scripts.load import *
  File "/opt/***/scripts/load.py", line 9, in <module>
    from docx import Document
ModuleNotFoundError: No module named 'docx'

[2025-08-19T09:04:03.919+0000] {taskinstance.py:2728} ERROR - Task failed with exception
Traceback (most recent call last):
  File "/home/airflow/.local/lib/python3.11/site-packages/airflow/models/taskinstance.py", line 444, in _execute_task
    result = _execute_callable(context=context, **execute_callable_kwargs)
             ^^^^^^^^^^^^^^^^^^^^^^^^^^^^^^^^^^^^^^^^^^^^^^^^^^^^^^^^^^^^^
  File "/home/airflow/.local/lib/python3.11/site-packages/airflow/models/taskinstance.py", line 414, in _execute_callable
    return execute_callable(context=context, **execute_callable_kwargs)
           ^^^^^^^^^^^^^^^^^^^^^^^^^^^^^^^^^^^^^^^^^^^^^^^^^^^^^^^^^^^^
  File "/home/airflow/.local/lib/python3.11/site-packages/airflow/operators/python.py", line 200, in execute
    return_value = self.execute_callable()
                   ^^^^^^^^^^^^^^^^^^^^^^^
  File "/home/airflow/.local/lib/python3.11/site-packages/airflow/operators/python.py", line 217, in execute_callable
    return self.python_callable(*self.op_args, **self.op_kwargs)
           ^^^^^^^^^^^^^^^^^^^^^^^^^^^^^^^^^^^^^^^^^^^^^^^^^^^^^
  File "/opt/airflow/dags/mamda_monthly_etl.py", line 92, in run_db_to_file_etl
    _fail_on_error_markers(result, [
  File "/opt/airflow/dags/mamda_monthly_etl.py", line 71, in _fail_on_error_markers
    raise RuntimeError(f"Detected error in child script output: {m}")
RuntimeError: Detected error in child script output: Traceback (most recent call last):
[2025-08-19T09:04:03.935+0000] {taskinstance.py:1149} INFO - Marking task as UP_FOR_RETRY. dag_id=mamda_monthly_etl_pipeline, task_id=run_db_to_file_etl, execution_date=20250819T085357, start_date=20250819T090403, end_date=20250819T090403
[2025-08-19T09:04:03.949+0000] {standard_task_runner.py:107} ERROR - Failed to execute job 25 for task run_db_to_file_etl (Detected error in child script output: Traceback (most recent call last):; 294)
[2025-08-19T09:04:03.986+0000] {local_task_job_runner.py:234} INFO - Task exited with return code 1
[2025-08-19T09:04:04.006+0000] {taskinstance.py:3309} INFO - 0 downstream tasks scheduled from follow-on schedule check
