[2025-08-26T11:39:51.144+0000] {taskinstance.py:1979} INFO - Dependencies all met for dep_context=non-requeueable deps ti=<TaskInstance: mamda_monthly_etl_pipeline.run_db_to_file_etl manual__2025-08-26T11:39:46.990962+00:00 [queued]>
[2025-08-26T11:39:51.155+0000] {taskinstance.py:1979} INFO - Dependencies all met for dep_context=requeueable deps ti=<TaskInstance: mamda_monthly_etl_pipeline.run_db_to_file_etl manual__2025-08-26T11:39:46.990962+00:00 [queued]>
[2025-08-26T11:39:51.156+0000] {taskinstance.py:2193} INFO - Starting attempt 1 of 1
[2025-08-26T11:39:51.176+0000] {taskinstance.py:2214} INFO - Executing <Task(PythonOperator): run_db_to_file_etl> on 2025-08-26 11:39:46.990962+00:00
[2025-08-26T11:39:51.182+0000] {standard_task_runner.py:60} INFO - Started process 78 to run task
[2025-08-26T11:39:51.185+0000] {standard_task_runner.py:87} INFO - Running: ['***', 'tasks', 'run', 'mamda_monthly_etl_pipeline', 'run_db_to_file_etl', 'manual__2025-08-26T11:39:46.990962+00:00', '--job-id', '321', '--raw', '--subdir', 'DAGS_FOLDER/mamda_monthly_etl.py', '--cfg-path', '/tmp/tmpmn7tsx8c']
[2025-08-26T11:39:51.187+0000] {standard_task_runner.py:88} INFO - Job 321: Subtask run_db_to_file_etl
[2025-08-26T11:39:51.235+0000] {task_command.py:423} INFO - Running <TaskInstance: mamda_monthly_etl_pipeline.run_db_to_file_etl manual__2025-08-26T11:39:46.990962+00:00 [running]> on host ea967ab0798b
[2025-08-26T11:39:51.321+0000] {taskinstance.py:2510} INFO - Exporting env vars: AIRFLOW_CTX_DAG_OWNER='mamda_etl' AIRFLOW_CTX_DAG_ID='mamda_monthly_etl_pipeline' AIRFLOW_CTX_TASK_ID='run_db_to_file_etl' AIRFLOW_CTX_EXECUTION_DATE='2025-08-26T11:39:46.990962+00:00' AIRFLOW_CTX_TRY_NUMBER='1' AIRFLOW_CTX_DAG_RUN_ID='manual__2025-08-26T11:39:46.990962+00:00'
[2025-08-26T11:39:51.323+0000] {mamda_monthly_etl.py:85} INFO - === START: DB -> FILE ETL ===
[2025-08-26T11:39:55.616+0000] {mamda_monthly_etl.py:99} INFO - DB->FILE STDOUT:
AVERTISSEMENT: Dossier externe non accessible ou non défini dans .env
Utilisation du dossier local à la place.
Utilisation du dossier local: /opt/***/data/fee_payouts
AVERTISSEMENT: Dossier externe non accessible ou non défini dans .env
Utilisation du dossier local à la place.
Utilisation du dossier local: /opt/***/data/fee_payouts
AVERTISSEMENT: Dossier externe non accessible ou non défini dans .env
Utilisation du dossier local à la place.
Utilisation du dossier local: /opt/***/data/fee_payouts
AVERTISSEMENT: Dossier externe non accessible ou non défini dans .env
Utilisation du dossier local à la place.
Utilisation du dossier local: /opt/***/data/fee_payouts

[2025-08-26T11:39:55.617+0000] {mamda_monthly_etl.py:101} WARNING - DB->FILE STDERR:
INFO:__main__:---- DÉMARRAGE DU PIPELINE DB -> FILE ----
INFO:__main__:--- Traitement pour base: sinauto_mcma_, type_aux: A ---
INFO:__main__:Données extraites avec succès pour sinauto_mcma_
INFO:__main__:sinauto_mcma_ : mapping réussi
INFO:__main__:sinauto_mcma_ : transformation réussie
ERROR:__main__:Erreur lors du traitement de sinauto_mcma_, type_aux=A : [Errno 13] Permission denied: '/opt/***/data/fee_payouts/Avocats'
INFO:__main__:--- Traitement pour base: sinauto_mcma_, type_aux: E ---
INFO:__main__:Données extraites avec succès pour sinauto_mcma_
INFO:__main__:sinauto_mcma_ : mapping réussi
INFO:__main__:sinauto_mcma_ : transformation réussie
ERROR:__main__:Erreur lors du traitement de sinauto_mcma_, type_aux=E : [Errno 13] Permission denied: '/opt/***/data/fee_payouts/Experts Automobiles'
INFO:__main__:--- Traitement pour base: sinauto_mcma_, type_aux: M ---
INFO:__main__:Données extraites avec succès pour sinauto_mcma_
INFO:__main__:sinauto_mcma_ : mapping réussi
INFO:__main__:sinauto_mcma_ : transformation réussie
ERROR:__main__:Erreur lors du traitement de sinauto_mcma_, type_aux=M : [Errno 13] Permission denied: '/opt/***/data/fee_payouts/Medecins'
INFO:__main__:--- Traitement pour base: sinauto_mcma_, type_aux: C ---
INFO:__main__:Données extraites avec succès pour sinauto_mcma_
INFO:__main__:sinauto_mcma_ : mapping réussi
INFO:__main__:sinauto_mcma_ : transformation réussie
ERROR:__main__:Erreur lors du traitement de sinauto_mcma_, type_aux=C : [Errno 13] Permission denied: '/opt/***/data/fee_payouts/Experts Comptables'
INFO:__main__:---- FIN DU PIPELINE DB -> FILE ----

[2025-08-26T11:39:55.619+0000] {mamda_monthly_etl.py:109} INFO - === DONE: DB -> FILE ETL ===
[2025-08-26T11:39:55.619+0000] {python.py:202} INFO - Done. Returned value was: None
[2025-08-26T11:39:55.633+0000] {taskinstance.py:1149} INFO - Marking task as SUCCESS. dag_id=mamda_monthly_etl_pipeline, task_id=run_db_to_file_etl, execution_date=20250826T113946, start_date=20250826T113951, end_date=20250826T113955
[2025-08-26T11:39:55.756+0000] {local_task_job_runner.py:234} INFO - Task exited with return code 0
[2025-08-26T11:39:55.793+0000] {taskinstance.py:3309} INFO - 0 downstream tasks scheduled from follow-on schedule check
