[2025-08-26T09:06:59.600+0000] {taskinstance.py:1979} INFO - Dependencies all met for dep_context=non-requeueable deps ti=<TaskInstance: mamda_monthly_etl_pipeline.check_status_files manual__2025-08-26T09:06:56.509970+00:00 [queued]>
[2025-08-26T09:06:59.610+0000] {taskinstance.py:1979} INFO - Dependencies all met for dep_context=requeueable deps ti=<TaskInstance: mamda_monthly_etl_pipeline.check_status_files manual__2025-08-26T09:06:56.509970+00:00 [queued]>
[2025-08-26T09:06:59.611+0000] {taskinstance.py:2193} INFO - Starting attempt 1 of 1
[2025-08-26T09:06:59.625+0000] {taskinstance.py:2214} INFO - Executing <Task(PythonOperator): check_status_files> on 2025-08-26 09:06:56.509970+00:00
[2025-08-26T09:06:59.630+0000] {standard_task_runner.py:60} INFO - Started process 143 to run task
[2025-08-26T09:06:59.633+0000] {standard_task_runner.py:87} INFO - Running: ['***', 'tasks', 'run', 'mamda_monthly_etl_pipeline', 'check_status_files', 'manual__2025-08-26T09:06:56.509970+00:00', '--job-id', '135', '--raw', '--subdir', 'DAGS_FOLDER/mamda_monthly_etl.py', '--cfg-path', '/tmp/tmpixbj5tmo']
[2025-08-26T09:06:59.635+0000] {standard_task_runner.py:88} INFO - Job 135: Subtask check_status_files
[2025-08-26T09:06:59.682+0000] {task_command.py:423} INFO - Running <TaskInstance: mamda_monthly_etl_pipeline.check_status_files manual__2025-08-26T09:06:56.509970+00:00 [running]> on host 9f5b6f3413d6
[2025-08-26T09:06:59.761+0000] {taskinstance.py:2510} INFO - Exporting env vars: AIRFLOW_CTX_DAG_OWNER='mamda_etl' AIRFLOW_CTX_DAG_ID='mamda_monthly_etl_pipeline' AIRFLOW_CTX_TASK_ID='check_status_files' AIRFLOW_CTX_EXECUTION_DATE='2025-08-26T09:06:56.509970+00:00' AIRFLOW_CTX_TRY_NUMBER='1' AIRFLOW_CTX_DAG_RUN_ID='manual__2025-08-26T09:06:56.509970+00:00'
[2025-08-26T09:06:59.762+0000] {mamda_monthly_etl.py:117} INFO - === CHECK: STATUS FILES ===
[2025-08-26T09:06:59.764+0000] {taskinstance.py:2728} ERROR - Task failed with exception
Traceback (most recent call last):
  File "/home/airflow/.local/lib/python3.11/site-packages/airflow/models/taskinstance.py", line 444, in _execute_task
    result = _execute_callable(context=context, **execute_callable_kwargs)
             ^^^^^^^^^^^^^^^^^^^^^^^^^^^^^^^^^^^^^^^^^^^^^^^^^^^^^^^^^^^^^
  File "/home/airflow/.local/lib/python3.11/site-packages/airflow/models/taskinstance.py", line 414, in _execute_callable
    return execute_callable(context=context, **execute_callable_kwargs)
           ^^^^^^^^^^^^^^^^^^^^^^^^^^^^^^^^^^^^^^^^^^^^^^^^^^^^^^^^^^^^
  File "/home/airflow/.local/lib/python3.11/site-packages/airflow/operators/python.py", line 200, in execute
    return_value = self.execute_callable()
                   ^^^^^^^^^^^^^^^^^^^^^^^
  File "/home/airflow/.local/lib/python3.11/site-packages/airflow/operators/python.py", line 217, in execute_callable
    return self.python_callable(*self.op_args, **self.op_kwargs)
           ^^^^^^^^^^^^^^^^^^^^^^^^^^^^^^^^^^^^^^^^^^^^^^^^^^^^^
  File "/opt/airflow/dags/mamda_monthly_etl.py", line 131, in check_for_new_status_files
    p.mkdir(parents=True, exist_ok=True)
  File "/usr/local/lib/python3.11/pathlib.py", line 1116, in mkdir
    os.mkdir(self, mode)
FileExistsError: [Errno 17] File exists: '/opt/airflow/data/fee_payouts_status'
[2025-08-26T09:06:59.778+0000] {taskinstance.py:1149} INFO - Marking task as FAILED. dag_id=mamda_monthly_etl_pipeline, task_id=check_status_files, execution_date=20250826T090656, start_date=20250826T090659, end_date=20250826T090659
[2025-08-26T09:06:59.789+0000] {standard_task_runner.py:107} ERROR - Failed to execute job 135 for task check_status_files ([Errno 17] File exists: '/opt/airflow/data/fee_payouts_status'; 143)
[2025-08-26T09:06:59.806+0000] {local_task_job_runner.py:234} INFO - Task exited with return code 1
[2025-08-26T09:06:59.829+0000] {taskinstance.py:3309} INFO - 0 downstream tasks scheduled from follow-on schedule check
